<?xml version="1.0" encoding="utf-8"?>
<!-- This URDF was automatically created by SolidWorks to URDF Exporter! Originally created by Stephen Brawner (brawner@gmail.com) 
     Commit Version: 1.6.0-1-g15f4949  Build Version: 1.6.7594.29634
     For more information, please see http://wiki.ros.org/sw_urdf_exporter -->
<robot
  name="project_arm_1">

   <!-- Used for fixing robot to Gazebo 'base_link' -->
  <link name="world"/>

  <joint name="fixed" type="fixed">
    <parent link="world"/>
    <child link="base_robot"/>
  </joint>

  <link
    name="base_robot">
    <inertial>
      <origin
        xyz="0.087847 0.068109 0.042187"
        rpy="0 0 0" />
      <mass
        value="0.72938" />
      <inertia
        ixx="0.0046602"
        ixy="-1.6887E-19"
        ixz="3.379E-19"
        iyy="0.0044952"
        iyz="3.2874E-20"
        izz="0.0046602" />
    </inertial>
    <visual>
      <origin
        xyz="0 0 0"
        rpy="0 0 0" />
      <geometry>
        <mesh
          filename="package://project_arm_1/meshes/base_robot.STL" />
      </geometry>
      <material
        name="">
        <color
          rgba="0.08627 0.6274 0.5215 1" />
      </material>
    </visual>
    <collision>
      <origin
        xyz="0 0 0"
        rpy="0 0 0" />
      <geometry>
        <mesh
          filename="package://project_arm_1/meshes/base_robot.STL" />
      </geometry>
    </collision>
  </link>
  <link
    name="link_1">
    <inertial>
      <origin
        xyz="1.3878E-17 0 0.026561"
        rpy="0 0 0" />
      <mass
        value="0.72688" />
      <inertia
        ixx="0.0012487"
        ixy="7.2378E-22"
        ixz="2.3667E-20"
        iyy="0.0013043"
        iyz="-4.708E-20"
        izz="0.0018887" />
    </inertial>
    <visual>
      <origin
        xyz="0 0 0"
        rpy="0 0 0" />
      <geometry>
        <mesh
          filename="package://project_arm_1/meshes/link_1.STL" />
      </geometry>
      <material
        name="">
        <color
          rgba="0.99999 0.76471 1E-05 1" />
      </material>
    </visual>
    <collision>
      <origin
        xyz="0 0 0"
        rpy="0 0 0" />
      <geometry>
        <mesh
          filename="package://project_arm_1/meshes/link_1.STL" />
      </geometry>
    </collision>
  </link>
  <joint
    name="joint_link_1"
    type="continuous">
    <origin
      xyz="0.087847 -0.042187 0.1015"
      rpy="0 0 0" />
    <parent
      link="base_robot" />
    <child
      link="link_1" />
    <axis
      xyz="0 0 1" />
  </joint>
  <link
    name="link_2">
    <inertial>
      <origin
        xyz="-0.048042 0 -0.0015"
        rpy="0 0 0" />
      <mass
        value="0.28718" />
      <inertia
        ixx="0.00013287"
        ixy="-6.435E-20"
        ixz="-2.567E-21"
        iyy="0.00064561"
        iyz="1.7428E-21"
        izz="0.00063883" />
    </inertial>
    <visual>
      <origin
        xyz="0 0 0"
        rpy="0 0 0" />
      <geometry>
        <mesh
          filename="package://project_arm_1/meshes/link_2.STL" />
      </geometry>
      <material
        name="">
        <color
          rgba="0.95294 1E-05 0.22353 1" />
      </material>
    </visual>
    <collision>
      <origin
        xyz="0 0 0"
        rpy="0 0 0" />
      <geometry>
        <mesh
          filename="package://project_arm_1/meshes/link_2.STL" />
      </geometry>
    </collision>
  </link>
  <joint
    name="joint_link_2"
    type="continuous">
    <origin
      xyz="0 0 0.086"
      rpy="3.1416 1.5708 0" />
    <parent
      link="link_1" />
    <child
      link="link_2" />
    <axis
      xyz="0 0 1" />
  </joint>
  <link
    name="link_3">
    <inertial>
      <origin
        xyz="-0.053463 -1.3878E-17 -0.0015"
        rpy="0 0 0" />
      <mass
        value="0.25625" />
      <inertia
        ixx="0.00011215"
        ixy="-4.1158E-20"
        ixz="-9.4092E-21"
        iyy="0.00055529"
        iyz="8.3589E-21"
        izz="0.0005528" />
    </inertial>
    <visual>
      <origin
        xyz="0 0 0"
        rpy="0 0 0" />
      <geometry>
        <mesh
          filename="package://project_arm_1/meshes/link_3.STL" />
      </geometry>
      <material
        name="">
        <color
          rgba="0.14118 0.44314 0.63922 1" />
      </material>
    </visual>
    <collision>
      <origin
        xyz="0 0 0"
        rpy="0 0 0" />
      <geometry>
        <mesh
          filename="package://project_arm_1/meshes/link_3.STL" />
      </geometry>
    </collision>
  </link>
  <joint
    name="joint_link_3"
    type="continuous">
    <origin
      xyz="-0.125 0 0"
      rpy="0 0 0" />
    <parent
      link="link_2" />
    <child
      link="link_3" />
    <axis
      xyz="0 0 1" />
  </joint>
  <link
    name="link_4">
    <inertial>
      <origin
        xyz="-0.041905 -2.0817E-17 -0.0015"
        rpy="0 0 0" />
      <mass
        value="0.21479" />
      <inertia
        ixx="9.1304E-05"
        ixy="7.8644E-23"
        ixz="-2.5535E-20"
        iyy="0.00032596"
        iyz="-9.3564E-21"
        izz="0.00036238" />
    </inertial>
    <visual>
      <origin
        xyz="0 0 0"
        rpy="0 0 0" />
      <geometry>
        <mesh
          filename="package://project_arm_1/meshes/link_4.STL" />
      </geometry>
      <material
        name="">
        <color
          rgba="0.4902 0.23529 0.59608 1" />
      </material>
    </visual>
    <collision>
      <origin
        xyz="0 0 0"
        rpy="0 0 0" />
      <geometry>
        <mesh
          filename="package://project_arm_1/meshes/link_4.STL" />
      </geometry>
    </collision>
  </link>
  <joint
    name="joint_link_4"
    type="continuous">
    <origin
      xyz="-0.125 0 0"
      rpy="0 0 0" />
    <parent
      link="link_3" />
    <child
      link="link_4" />
    <axis
      xyz="0 0 1" />
  </joint>


  <gazebo>
    <plugin name="gazebo_ros_control" filename="libgazebo_ros_control.so">
      <robotNamespace>/arm_robot_1</robotNamespace>
      <robotSimType>gazebo_ros_control/DefaultRobotHWSim</robotSimType>
    </plugin>
  </gazebo>

  <transmission name="trans1">
    <type>transmission_interface/SimpleTransmission</type>
    <joint name="joint_link_1">
      <hardwareInterface>hardware_interface/EffortJointInterface</hardwareInterface>
    </joint>
    <actuator name="motor1">
      <hardwareInterface>hardware_interface/EffortJointInterface</hardwareInterface>
      <mechanicalReduction>1</mechanicalReduction>
    </actuator>
  </transmission>


  <transmission name="trans2">
    <type>transmission_interface/SimpleTransmission</type>
    <joint name="joint_link_2">
      <hardwareInterface>hardware_interface/EffortJointInterface</hardwareInterface>
    </joint>
    <actuator name="motor2">
      <hardwareInterface>hardware_interface/EffortJointInterface</hardwareInterface>
      <mechanicalReduction>1</mechanicalReduction>
    </actuator>
  </transmission>

  <transmission name="trans3">
    <type>transmission_interface/SimpleTransmission</type>
    <joint name="joint_link_3">
      <hardwareInterface>hardware_interface/EffortJointInterface</hardwareInterface>
    </joint>
    <actuator name="motor3">
      <hardwareInterface>hardware_interface/EffortJointInterface</hardwareInterface>
      <mechanicalReduction>1</mechanicalReduction>
    </actuator>
  </transmission>

  <transmission name="trans4">
    <type>transmission_interface/SimpleTransmission</type>
    <joint name="joint_link_4">
      <hardwareInterface>hardware_interface/EffortJointInterface</hardwareInterface>
    </joint>
    <actuator name="motor4">
      <hardwareInterface>hardware_interface/EffortJointInterface</hardwareInterface>
      <mechanicalReduction>1</mechanicalReduction>
    </actuator>
  </transmission>


</robot>